<?xml version="1.0"?>
<robot name="agv_with_casters" xmlns:xacro="http://www.ros.org/wiki/xacro">

  <xacro:property name="pi" value="3.1415926535897931"/>

  <!-- ================= inertia macro ================= -->
  <xacro:macro name="inertial_cylinder" params="mass length radius">
    <inertial>
      <mass value="${mass}" />
      <inertia
        ixx="${(1/12) * mass * (3*radius*radius + length*length)}"
        ixy="0.0" ixz="0.0"
        iyy="${(1/12) * mass * (3*radius*radius + length*length)}"
        iyz="0.0"
        izz="${(1/2) * mass * (radius*radius)}" />
    </inertial>
  </xacro:macro>

  <!-- ================= materials ================= -->
  <material name="black"><color rgba="0 0 0 1"/></material>
  <material name="silver"><color rgba="0.75 0.75 0.75 1"/></material>

  <!-- ================= base_link (NO PHYSICS) ================= -->
  <link name="base_link"/>

  <!-- ================= chassis (PHYSICS BODY) ================= -->
  <joint name="base_to_chassis" type="fixed">
    <parent link="base_link"/>
    <child link="chassis_link"/>
  </joint>

  <link name="chassis_link">
    <visual>
      <geometry><box size="0.45 0.35 0.24"/></geometry>
      <origin xyz="0 0 0.12"/>
      <material name="silver"/>
    </visual>
    <collision>
      <geometry><box size="0.900 0.590 0.24"/></geometry>
      <origin xyz="0 0 0.12"/>
    </collision>
    <inertial>
      <mass value="20.0"/>
      <origin xyz="0 0 0.12"/>
      <inertia
        ixx="1.2"
        ixy="0.0" ixz="0.0"
        iyy="2.0"
        iyz="0.0"
        izz="2.5"/>
    </inertial>
  </link>

  <!-- ================= caster macro ================= -->
  <xacro:macro name="caster" params="name x y">
    <link name="${name}_link">
      <visual>
        <geometry><sphere radius="0.0315"/></geometry>
        <material name="black"/>
      </visual>
      <collision>
        <geometry><sphere radius="0.0315"/></geometry>
      </collision>
      <inertial>
        <mass value="0.3"/>
        <inertia
          ixx="0.0001"
          ixy="0.0" ixz="0.0"
          iyy="0.0001"
          iyz="0.0"
          izz="0.0001"/>
      </inertial>
    </link>

    <joint name="${name}_joint" type="fixed">
      <parent link="chassis_link"/>
      <child link="${name}_link"/>
      <origin xyz="${x} ${y} -0.052"/>
    </joint>

    <gazebo reference="${name}_link">
      <mu1>0.2</mu1>
      <mu2>0.2</mu2>
    </gazebo>
  </xacro:macro>

  <!-- ================= casters ================= -->
  <xacro:caster name="caster_fr" x="0.2993"  y="-0.260"/>
  <xacro:caster name="caster_fl" x="0.2993"  y="0.260"/>
  <xacro:caster name="caster_rr" x="-0.2993" y="-0.260"/>
  <xacro:caster name="caster_rl" x="-0.2993" y="0.260"/>

  <!-- ================= right wheel ================= -->
  <link name="right_wheel">
    <visual>
      <geometry><cylinder radius="0.075" length="0.05"/></geometry>
      <material name="black"/>
    </visual>
    <collision>
      <geometry><cylinder radius="0.075" length="0.05"/></geometry>
    </collision>
    <xacro:inertial_cylinder mass="0.5" length="0.05" radius="0.075"/>
  </link>
    <gazebo reference="right_wheel">
        <material>Gazebo/Black</material>
    </gazebo>
  <joint name="right_wheel_joint" type="continuous">
    <parent link="chassis_link"/>
    <child link="right_wheel"/>
    <origin xyz="0 -0.2397 -0.00973" rpy="${pi/2} 0 0"/>
    <axis xyz="0 0 -1"/>
  </joint>

  <!-- ================= left wheel ================= -->
  <link name="left_wheel">
    <visual>
      <geometry><cylinder radius="0.075" length="0.05"/></geometry>
      <material name="black"/>
    </visual>
    <collision>
      <geometry><cylinder radius="0.075" length="0.05"/></geometry>
    </collision>
    <xacro:inertial_cylinder mass="0.5" length="0.05" radius="0.075"/>
  </link>
    <gazebo reference="left_wheel">
        <material>Gazebo/Black</material>
    </gazebo>

  <joint name="left_wheel_joint" type="continuous">
    <parent link="chassis_link"/>
    <child link="left_wheel"/>
    <origin xyz="0 0.2397 -0.00973" rpy="-${pi/2} 0 0"/>
    <axis xyz="0 0 1"/>
  </joint>

</robot>
